# Guia Completo sobre `try...catch` em JavaScript

## Introdução

Em JavaScript, a manipulação adequada de erros é essencial para o desenvolvimento de aplicações robustas e confiáveis. O uso da estrutura `try...catch` permite que os desenvolvedores capturem e tratem exceções de forma eficaz, evitando que erros interrompam a execução do programa. Este guia explora detalhadamente o funcionamento do `try...catch`, incluindo sua sintaxe, uso do bloco `finally`, melhores práticas e exemplos práticos.

## Sintaxe do `try...catch`

A estrutura básica do `try...catch` é composta por dois blocos principais:

```javascript
try {
  // Código que pode gerar uma exceção
} catch (erro) {
  // Código para lidar com a exceção
}
```

**try**: Contém o código que pode potencialmente gerar uma exceção.

**catch**: Executado se uma exceção for lançada no bloco try. O parâmetro erro contém informações sobre o erro ocorrido.

## Exemplo Básico

```js
try {
  let resultado = 10 / x; // 'x' não está definido
} catch (erro) {
  console.error("Ocorreu um erro:", erro.message);
}
```

Neste exemplo, como x não está definido, uma exceção é lançada e capturada pelo bloco catch, exibindo a mensagem de erro correspondente.

## O Bloco `finally`

Além dos blocos try e catch, o finally pode ser utilizado para executar código que deve ocorrer independentemente de uma exceção ter sido lançada ou não. A sintaxe é a seguinte:

```js
try {
  // Código que pode gerar uma exceção
} catch (erro) {
  // Código para lidar com a exceção
} finally {
  // Código que será executado sempre
}
```

## Exemplo com finally

```js
function dividir(a, b) {
  try {
    if (b === 0) {
      throw new Error("Divisão por zero não é permitida.");
    }
    return a / b;
  } catch (erro) {
    console.error(erro.message);
  } finally {
    console.log("Operação concluída.");
  }
}

dividir(10, 0);
```

Neste caso, o bloco finally será executado independentemente de ocorrer uma exceção, garantindo que "Operação concluída." seja sempre exibido.

## Lançando Exceções com throw

O operador `throw` permite que você lance exceções personalizadas em seu código. Isso é útil para criar mensagens de erro específicas ou para interromper a execução quando determinadas condições não são atendidas.

## Exemplo de Uso do throw

```js
function verificarIdade(idade) {
  if (idade < 18) {
    throw new Error("Idade mínima requerida é 18 anos.");
  }
  console.log("Acesso permitido.");
}

try {
  verificarIdade(16);
} catch (erro) {
  console.error(erro.message);
}
```

Aqui, se a idade for inferior a 18, uma exceção é lançada e capturada pelo bloco catch, exibindo a mensagem de erro correspondente.

## Melhores Práticas no Uso de try...catch

1. Isolar Código Suscetível a Erros: Envolva apenas o código que pode gerar exceções no bloco try, mantendo o restante do código fora dele para facilitar a leitura e manutenção.

2. Especificidade nas Mensagens de Erro: Forneça mensagens de erro claras e específicas para facilitar a identificação e resolução de problemas.

3. Evitar Captura Genérica de Erros: Sempre que possível, capture tipos específicos de erros para evitar mascarar problemas inesperados.

4. Utilizar o Bloco finally para Limpeza: Use o bloco finally para liberar recursos ou executar tarefas de limpeza que devem ocorrer independentemente de uma exceção ter sido lançada.

5. Não Abusar do try...catch: Evite envolver grandes blocos de código com try...catch. Em vez disso, use-o de forma estratégica em partes do código onde erros são mais prováveis.

6. Manter o Usuário Informado: Em aplicações voltadas para o usuário, forneça feedback adequado quando ocorrerem erros, mantendo uma boa experiência do usuário.

## Tratamento de Erros Assíncronos

O `try...catch` tradicional não captura exceções em operações `assíncronas`, como chamadas `setTimeout` ou `fetch`. Para tratar erros em promessas, utilize o método `.catch()` ou a sintaxe `async/await` com `try...catch`.

## Exemplo com `async/await`

```js
async function obterDados(url) {
  try {
    let resposta = await fetch(url);
    if (!resposta.ok) {
      throw new Error(`Erro HTTP: ${resposta.status}`);
    }
    let dados = await resposta.json();
    return dados;
  } catch (erro) {
    console.error("Erro ao obter dados:", erro.message);
  }
}

obterDados("https://api.exemplo.com/dados");
```

Neste exemplo, qualquer erro ocorrido durante a requisição ou processamento da resposta será capturado pelo bloco catch.

## Conclusão

O uso adequado do try...catch em JavaScript é fundamental para criar aplicações robustas e resilientes a erros. Ao seguir as melhores práticas e compreender as nuances do tratamento de exceções, os desenvolvedores podem melhorar significativamente a estabilidade e a confiabilidade de suas aplicações.
